<?xml version="1.0"?>

<!-- Make the namespace of the robot-->
<robot xmlns:xacro="http://www.ros.org/wiki/xacro" name="ur10e">
    
    <!--======================================define_parameter=======================================-->
        <!--Define constants-->
        <xacro:property name="d_2PI" value="6.283185307179586"/>
        <xacro:property name="d_PI" value="3.141592653589793"/>
        <xacro:property name="d_half_PI" value="1.5707963267948966"/>


        <!--Define Rviz colors-->
        <material name="LightBlue">
            <color rgba="0.589 0.793 1.0 1.0"/>
        </material>
        <material name="LightGrey">
            <color rgba="0.7 0.7 0.7 1.0"/>
        </material>
        <material name="Yellow">
            <color rgba="1.0 1.0 0.0 1.0"/>
        </material>

    <!--======================================ur10e_arm=======================================-->
    <!--== define ur10e_arm ==-->
    <xacro:macro name="ur10e_arm_defined" params="">
        <!--world link-->
        <link name="world"/>

        <joint name="world_joint" type="fixed">
            <origin xyz="0.0 0.0 0.0" rpy="0.0 0.0 0.0"/>
            <parent link="world"/>
            <child link="base_link"/>
        </joint>

        <!-- links: main serial chain -->
        <link name="base_link"/>

        <link name="base_link_inertia">
            <visual>
                <origin rpy="0 0 0" xyz="0 0 0.03"/>
                <geometry>
                    <cylinder radius="0.095" length="0.06"/>
                </geometry>
                <material name="LightGrey"/>
            </visual>
            <collision>
                <origin rpy="0 0 0" xyz="0 0 0.03"/>
                <geometry>
                    <cylinder radius="0.095" length="0.06"/>
                </geometry>
            </collision>
            <inertial>
                <mass value="4.0"/>
                <origin rpy="0 0 0" xyz="0 0 0"/>
                <inertia ixx="0.0061063308908" ixy="0.0" ixz="0.0" iyy="0.0061063308908" iyz="0.0" izz="0.01125"/>
            </inertial>
        </link>

        <link name="shoulder_link">
            <visual>
                <origin rpy="0 0 0" xyz="0 0 -0.06035"/>
                <geometry>
                    <cylinder radius="0.06035" length="0.1207"/>
                </geometry>
                <material name="LightGrey"/>
            </visual>
            <collision>
                <origin rpy="0 0 0" xyz="0 0 -0.06035"/>
                <geometry>
                    <cylinder radius="0.06035" length="0.1207"/>
                </geometry>
            </collision>
            <inertial>
                <mass value="7.778"/>
                <origin rpy="0 0 0" xyz="0 0 0"/>
                <inertia ixx="0.03147431257693659" ixy="0.0" ixz="0.0" iyy="0.03147431257693659" iyz="0.0" izz="0.021875624999999996"/>
            </inertial>
        </link>

        <link name="upper_arm_link">
            <visual>
                <origin rpy="0 -${d_half_PI} 0" xyz="-0.30635 0 0.175"/>
                <geometry>
                    <cylinder radius="0.06035" length="0.6127"/>
                </geometry>
                <material name="LightGrey"/>
            </visual>
            <collision>
                <origin rpy="0 -${d_half_PI} 0" xyz="-0.30635 0 0.175"/>
                <geometry>
                    <cylinder radius="0.06035" length="0.6127"/>
                </geometry>
            </collision>
            <inertial>
                <mass value="12.93"/>
                <origin rpy="0 ${d_half_PI} 0" xyz="-0.306 0.0 0.175"/>
                <inertia ixx="0.42175380379841093" ixy="0.0" ixz="0.0" iyy="0.42175380379841093" iyz="0.0" izz="0.03636562499999999"/>
            </inertial>
        </link>

        <link name="forearm_link">
            <visual>
                <origin rpy="0 -${d_half_PI} 0" xyz="-0.285775 0 0.0393"/>
                <geometry>
                    <cylinder radius="0.06035" length="0.57155"/>
                </geometry>
                <material name="LightGrey"/>
            </visual>
            <collision>
                <origin rpy="0 -${d_half_PI} 0" xyz="-0.285775 0 0.0393"/>
                <geometry>
                    <cylinder radius="0.06035" length="0.57155"/>
                </geometry>
            </collision>
            <inertial>
                <mass value="3.87"/>
                <origin rpy="0 ${d_half_PI} 0" xyz="-0.285775 0.0 0.0393"/>
                <inertia ixx="0.11079302548902206" ixy="0.0" ixz="0.0" iyy="0.11079302548902206" iyz="0.0" izz="0.010884375"/>
            </inertial>
        </link>
    
        <link name="wrist_1_link">
            <visual>
                <origin rpy="${d_half_PI} 0 0" xyz="0 -0.059925 0"/>
                <geometry>
                    <cylinder radius="0.06035" length="0.11985"/>
                </geometry>
                <material name="LightGrey"/>
            </visual>
            <collision>
                <origin rpy="${d_half_PI} 0 0" xyz="0 -0.059925 0"/>
                <geometry>
                    <cylinder radius="0.06035" length="0.11985"/>
                </geometry>
            </collision>
            <inertial>
                <mass value="1.96"/>
                <origin rpy="0 0 0" xyz="0 0 0"/>
                <inertia ixx="0.005108247956699999" ixy="0.0" ixz="0.0" iyy="0.005108247956699999" iyz="0.0" izz="0.005512499999999999"/>
            </inertial>
        </link>

        <link name="wrist_2_link">
            <visual>
                <origin rpy="-${d_half_PI} 0 0" xyz="0 0.058275 0"/>
                <geometry>
                    <cylinder radius="0.06035" length="0.11655"/>
                </geometry>
                <material name="LightGrey"/>
            </visual>
            <collision>
                <origin rpy="-${d_half_PI} 0 0" xyz="0 0.058275 0"/>
                <geometry>
                    <cylinder radius="0.06035" length="0.11655"/>
                </geometry>
            </collision>
            <inertial>
                <mass value="1.96"/>
                <origin rpy="0 0 0" xyz="0 0 0"/>
                <inertia ixx="0.005108247956699999" ixy="0.0" ixz="0.0" iyy="0.005108247956699999" iyz="0.0" izz="0.005512499999999999"/>
            </inertial>
        </link>

        <link name="wrist_3_link">
            <visual>
                <origin rpy="0 0 0" xyz="0 0 0.025"/>
                <geometry>
                    <cylinder radius="0.06035" length="0.05"/>
                </geometry>
                <material name="LightGrey"/>
            </visual>
            <collision>
                <origin rpy="0 0 0" xyz="0 0 0.025"/>
                <geometry>
                    <cylinder radius="0.06035" length="0.05"/>
                </geometry>
            </collision>
            <inertial>
                <mass value="0.202"/>
                <origin rpy="0 0 0" xyz="0.0 0.0 -0.025"/>
                <inertia ixx="0.00014434577559500002" ixy="0.0" ixz="0.0" iyy="0.00014434577559500002" iyz="0.0" izz="0.00020452500000000002"/>
            </inertial>
        </link>

        <link name="flange_base">
            <visual>
                <origin xyz="0.0 0.0 0.005" rpy="0.0 0.0 0.0"/>
                <geometry>
                    <box size="0.1207 0.2 0.01"/>
                </geometry>
                <material name="LightGrey"/>
            </visual>
            <collision>
                <origin xyz="0.0 0.0 0.005" rpy="0.0 0.0 0.0"/>
                <geometry>
                    <box size="0.1207 0.2 0.01"/>
                </geometry>
            </collision>
            <inertial>
                <origin xyz="0 0 0.005" rpy="0 0 0"/>
                <mass value="0.001"/>
                <inertia ixx="1e-12" ixy="0.0" ixz="0.0" iyy="1e-12" iyz="0.0" izz="1e-12"/>
            </inertial>
        </link>

        <!-- joints: main serial chain -->
        <joint name="base_link-base_link_inertia" type="fixed">
            <parent link="base_link"/>
            <child link="base_link_inertia"/>
            <origin rpy="0 0 0" xyz="0 0 0"/>
        </joint>

        <joint name="shoulder_pan_joint" type="revolute">
            <parent link="base_link_inertia"/>
            <child link="shoulder_link"/>
            <origin rpy="0 0 0" xyz="0 0 0.1807"/>
            <axis xyz="0 0 1"/>
            <limit effort="330.0" lower="-${d_2PI}" upper="${d_2PI}" velocity="2.0943951023931953"/>
            <dynamics damping="0" friction="0"/>
        </joint>

        <joint name="shoulder_lift_joint" type="revolute">
            <parent link="shoulder_link"/>
            <child link="upper_arm_link"/>
            <origin rpy="1.570796327 0 0" xyz="0 0 0"/>
            <axis xyz="0 0 1"/>
            <limit effort="330.0" lower="-${d_2PI}" upper="${d_2PI}" velocity="2.0943951023931953"/>
            <dynamics damping="0" friction="0"/>
        </joint>

        <joint name="elbow_joint" type="revolute">
            <parent link="upper_arm_link"/>
            <child link="forearm_link"/>
            <origin rpy="0 0 0" xyz="-0.6127 0 0"/>
            <axis xyz="0 0 1"/>
            <limit effort="150.0" lower="-${d_PI}" upper="${d_PI}" velocity="${d_PI}"/>
            <dynamics damping="0" friction="0"/>
        </joint>

        <joint name="wrist_1_joint" type="revolute">
            <parent link="forearm_link"/>
            <child link="wrist_1_link"/>
            <origin rpy="0 0 0" xyz="-0.57155 0 0.17415"/>
            <axis xyz="0 0 1"/>
            <limit effort="56.0" lower="-${d_2PI}" upper="${d_2PI}" velocity="${d_PI}"/>
            <dynamics damping="0" friction="0"/>
        </joint>

        <joint name="wrist_2_joint" type="revolute">
            <parent link="wrist_1_link"/>
            <child link="wrist_2_link"/>
            <origin rpy="1.570796327 0 0" xyz="0 -0.11985 -2.458164590756244e-11"/>
            <axis xyz="0 0 1"/>
            <limit effort="56.0" lower="-${d_2PI}" upper="${d_2PI}" velocity="${d_PI}"/>
            <dynamics damping="0" friction="0"/>
        </joint>

        <joint name="wrist_3_joint" type="revolute">
            <parent link="wrist_2_link"/>
            <child link="wrist_3_link"/>
            <origin rpy="${d_half_PI} ${d_PI} ${d_PI}" xyz="0 0.11655 -2.390480459346185e-11"/>
            <axis xyz="0 0 1"/>
            <limit effort="56.0" lower="-${d_2PI}" upper="${d_2PI}" velocity="${d_PI}"/>
            <dynamics damping="0" friction="0"/>
        </joint>

        <joint name="wrist_3-flange_base" type="fixed">
            <parent link="wrist_3_link"/>
            <child link="flange_base"/>
            <origin rpy="0 0 ${d_half_PI}" xyz="0 0 0.05"/>
        </joint>
        
    
        <!-- links: plus serial chain ：links without mass, just for visualization -->
        <link name="shoulder_link_plus">
            <visual>
                <origin rpy="0 0 0" xyz="0 0 -0.1107"/>
                <geometry>
                    <cylinder radius="0.06035" length="0.02"/>
                </geometry>
                <material name="LightBlue"/>
            </visual>
            <collision>
                <origin rpy="0 0 0" xyz="0 0 -0.1107"/>
                <geometry>
                    <cylinder radius="0.06035" length="0.02"/>
                </geometry>
            </collision>
            <inertial>
                <mass value="0.001"/>
                <origin rpy="0 0 0" xyz="0 0 -0.1107"/>
                <inertia ixx="1e-12" ixy="0.0" ixz="0.0" iyy="1e-12" iyz="0.0" izz="1e-12"/>
            </inertial>
        </link>

        <link name="upper_arm_link_plus">
            <visual>
                <origin rpy="0 0 0" xyz="0 0 0.0875"/>
                <geometry>
                    <cylinder radius="0.06035" length="0.2957"/>
                </geometry>
                <material name="LightBlue"/>
            </visual>
            <collision>
                <origin rpy="0 0 0" xyz="0 0 0.0875"/>
                <geometry>
                    <cylinder radius="0.06035" length="0.2957"/>
                </geometry>
            </collision>
            <inertial>
                <mass value="0.001"/>
                <origin rpy="0 0 0" xyz="0 0 0.0875"/>
                <inertia ixx="1e-12" ixy="0.0" ixz="0.0" iyy="1e-12" iyz="0.0" izz="1e-12"/>
            </inertial>
        </link>

        <link name="forearm_link_plus">
            <visual>
                <origin rpy="0 0 0" xyz="0 0 0.10715"/>
                <geometry>
                    <cylinder radius="0.06035" length="0.2564"/>
                </geometry>
                <material name="LightBlue"/>
            </visual>
            <collision>
                <origin rpy="0 0 0" xyz="0 0 0.10715"/>
                <geometry>
                    <cylinder radius="0.06035" length="0.2564"/>
                </geometry>
            </collision>
            <inertial>
                <mass value="0.001"/>
                <origin rpy="0 0 0" xyz="0 0 0.10715"/>
                <inertia ixx="1e-12" ixy="0.0" ixz="0.0" iyy="1e-12" iyz="0.0" izz="1e-12"/>
            </inertial>
        </link>

        <link name="wrist_1_link_plus">
            <visual>
                <origin rpy="0 0 0" xyz="0 0 -0.067425"/>
                <geometry>
                    <cylinder radius="0.06035" length="0.25555"/>
                </geometry>
                <material name="LightBlue"/>
            </visual>
            <collision>
                <origin rpy="0 0 0" xyz="0 0 -0.067425"/>
                <geometry>
                    <cylinder radius="0.06035" length="0.25555"/>
                </geometry>
            </collision>
            <inertial>
                <mass value="0.001"/>
                <origin rpy="0 0 0" xyz="0 0 -0.067425"/>
                <inertia ixx="1e-12" ixy="0.0" ixz="0.0" iyy="1e-12" iyz="0.0" izz="1e-12"/>
            </inertial>
        </link>

        <link name="wrist_2_link_plus">
            <visual>
                <origin rpy="0 0 0" xyz="0 0 0.030175"/>
                <geometry>
                    <cylinder radius="0.06035" length="0.06035"/>
                </geometry>
                <material name="LightBlue"/>
            </visual>
            <collision>
                <origin rpy="0 0 0" xyz="0 0 0.030175"/>
                <geometry>
                    <cylinder radius="0.06035" length="0.06035"/>
                </geometry>
            </collision>
            <inertial>
                <mass value="0.001"/>
                <origin rpy="0 0 0" xyz="0 0 0.030175"/>
                <inertia ixx="1e-12" ixy="0.0" ixz="0.0" iyy="1e-12" iyz="0.0" izz="1e-12"/>
            </inertial>
        </link>

        <link name="wrist_3_link_plus">
            <visual>
                <origin rpy="0 0 0" xyz="0 0 0.005"/>
                <geometry>
                    <cylinder radius="0.06035" length="0.01"/>
                </geometry>
                <material name="LightBlue"/>
            </visual>
            <collision>
                <origin rpy="0 0 0" xyz="0 0 0.005"/>
                <geometry>
                    <cylinder radius="0.06035" length="0.01"/>
                </geometry>
            </collision>
            <inertial>
                <mass value="0.001"/>
                <origin rpy="0 0 0" xyz="0 0 0.005"/>
                <inertia ixx="1e-12" ixy="0.0" ixz="0.0" iyy="1e-12" iyz="0.0" izz="1e-12"/>
            </inertial>
        </link>

        <!-- joints: plus serial chain -->
        <joint name="shoulder_pan_joint_plus" type="fixed">
            <parent link="base_link_inertia"/>
            <child link="shoulder_link_plus"/>
            <origin rpy="0 0 0" xyz="0 0 0.1807"/>
        </joint>

        <joint name="shoulder_lift_joint_plus" type="fixed">
            <parent link="shoulder_link"/>
            <child link="upper_arm_link_plus"/>
            <origin rpy="1.570796327 0 0" xyz="0 0 0"/>
        </joint>

        <joint name="elbow_joint_plus" type="fixed">
            <parent link="upper_arm_link"/>
            <child link="forearm_link_plus"/>
            <origin rpy="0 0 0" xyz="-0.6127 0 0"/><dynamics damping="0" friction="0"/>
        </joint>

        <joint name="wrist_1_joint_plus" type="fixed">
            <parent link="forearm_link"/>
            <child link="wrist_1_link_plus"/>
            <origin rpy="0 0 0" xyz="-0.57155 0 0.17415"/>
        </joint>

        <joint name="wrist_2_joint_plus" type="fixed">
            <parent link="wrist_1_link"/>
            <child link="wrist_2_link_plus"/>
            <origin rpy="1.570796327 0 0" xyz="0 -0.11985 -2.458164590756244e-11"/>
        </joint>

        <joint name="wrist_3_joint_plus" type="fixed">
            <parent link="wrist_2_link"/>
            <child link="wrist_3_link_plus"/>
            <origin rpy="${d_half_PI} ${d_PI} ${d_PI}" xyz="0 0.11655 -2.390480459346185e-11"/>
        </joint>
    </xacro:macro>

    <!--== load ur10e_arm ==-->
    <xacro:ur10e_arm_defined/>

    <!--======================================custom_grip=======================================-->
    <!--== define custom_grip ==-->
    <xacro:macro name="custom_grip_defined" params="">
        <!-- parameter defined -->
        <xacro:property name="mass_flange" value="0.1" />
        <xacro:property name="mass_gripper_link" value="0.025" />

        <!-- custom_grip defined -->
        <joint name="flange_base-flange" type="fixed">
            <parent link="flange_base"/>
            <child link="flange"/>
            <origin rpy="0 0 0" xyz="0 0 0.0"/>
        </joint>

        <link name="flange">
            <visual>
                <origin xyz="0.0 0.0 0.015" rpy="0.0 0.0 0.0"/>
                <geometry>
                    <box size="0.1207 0.2 0.01"/>
                </geometry>
                <material name="Yellow"/>
            </visual>
            <collision>
                <origin xyz="0.0 0.0 0.015" rpy="0.0 0.0 0.0"/>
                <geometry>
                    <box size="0.1207 0.2 0.01"/>
                </geometry>
            </collision>
            <inertial>
                <origin xyz="0 0 0.01" rpy="0 0 0"/>
                <mass value="${mass_flange}"/>
                <inertia
                    ixx="${mass_flange / 12.0 * (0.02*0.02 + 0.2*0.2)}" ixy="0.0" ixz="0.0"
                    iyy="${mass_flange / 12.0 * (0.02*0.02 + 0.1207*0.1207)}" iyz="0.0"
                    izz="${mass_flange / 12.0 * (0.1207*0.1207 + 0.2*0.2)}" />
            </inertial>
        </link> 

        <joint name="gripper_joint_1" type="prismatic">
            <origin xyz="0.0 0.025 0.02" rpy="-${d_half_PI} 0.0 0.0"/>
            <parent link="flange"/>
            <child link="gripper_link_1"/>
            <axis xyz="0 0 1"/>
            <limit lower="0.0" upper="0.04" effort="100.0" velocity="0.5"/>
        </joint>

        <link name="gripper_link_1">
            <visual>
                <origin xyz="0.0 -0.05 0.0" rpy="${d_half_PI} 0.0 0.0"/>
                <geometry>
                    <box size="0.025 0.025 0.1"/>
                </geometry>
                <material name="Yellow"/>
            </visual>
            <collision>
                <origin xyz="0.0 -0.05 0.0" rpy="${d_half_PI} 0.0 0.0"/>
                <geometry>
                    <box size="0.025 0.025 0.1"/>
                </geometry>
            </collision>
            <inertial>
                <!-- To do: chech the compatibility of origin rpy and inertia matrix-->
                <origin xyz="0.0 -0.05 0.0" rpy="${d_half_PI} 0.0 0.0"/>
                <mass value="${mass_gripper_link}"/>
                <inertia
                    ixx="${mass_gripper_link / 12.0 * (0.025*0.025 + 0.1*0.1)}" ixy="0.0" ixz="0.0"
                    iyy="${mass_gripper_link / 12.0 * (0.025*0.025 + 0.025*0.025)}" iyz="0.0"
                    izz="${mass_gripper_link / 12.0 * (0.025*0.025 + 0.1*0.1)}" />
            </inertial>
        </link>

        <joint name="gripper_joint_2" type="prismatic">
            <origin xyz="0.0 -0.025 0.02" rpy="${d_half_PI} 0.0 0.0"/>
            <parent link="flange"/>
            <child link="gripper_link_2"/>
            <axis xyz="0 0 1"/>
            <limit lower="0.0" upper="0.04" effort="100.0" velocity="0.5"/>
            <mimic joint="gripper_joint_1" multiplier="1.0" offset="0.0" />
        </joint>

        <link name="gripper_link_2">
            <visual>
                <origin xyz="0.0 0.05 0.0" rpy="${d_half_PI} 0.0 0.0"/>
                <geometry>
                    <box size="0.025 0.025 0.1"/>
                </geometry>
                <material name="Yellow"/>
            </visual>
            <collision>
                <origin xyz="0.0 0.05 0.0" rpy="${d_half_PI} 0.0 0.0"/>
                <geometry>
                    <box size="0.025 0.025 0.1"/>
                </geometry>
            </collision>
            <inertial>
                <!-- To do: chech the compatibility of origin rpy and inertia matrix-->
                <origin xyz="0.0 0.05 0.0" rpy="${d_half_PI} 0.0 0.0"/>
                <mass value="${mass_gripper_link}"/>
                <inertia
                    ixx="${mass_gripper_link / 12.0 * (0.025*0.025 + 0.1*0.1)}" ixy="0.0" ixz="0.0"
                    iyy="${mass_gripper_link / 12.0 * (0.025*0.025 + 0.025*0.025)}" iyz="0.0"
                    izz="${mass_gripper_link / 12.0 * (0.025*0.025 + 0.1*0.1)}" />
            </inertial>
        </link>
    </xacro:macro>

    <!--== load custom_grip ==-->
    <xacro:custom_grip_defined/>

    <!--======================================define_virutual_mimic_joint_to_solve_gazebo_moveit_bug=======================================-->
    <!--== define virtual mimic joint ==-->
    <xacro:macro name="virtual_mimic_joint_defined" params="">
        <link name="virtual_link_1"/>
        <joint name="gripper_joint_2_mimic" type="fixed">
            <parent link="world" />
            <child link="virtual_link_1" />
        </joint>
    </xacro:macro>

    <!--== load virtual mimic joint ==-->
    <xacro:virtual_mimic_joint_defined/>
        
</robot>